<mujoco model="adam">
    <compiler angle="radian" meshdir="meshes" autolimits="true" />

    <default>
        <joint axis="0 1 0" range="-6.28319 6.28319" />
        <position ctrlrange="-6.2831 6.2831" />

        <default class="visual">
            <geom type="mesh" contype="0" conaffinity="0" group="2" />
        </default>
        <default class="collision">
            <geom type="capsule" group="3" />
            <default class="eef_collision">
                <geom type="cylinder" />
            </default>
        </default>
        <site size="0.001" rgba="0.5 0.5 0.5 0.3" group="4" />

        <!-- Reference: https://www.universal-robots.com/articles/ur/robot-care-maintenance/max-joint-torques/ -->
        <default class="size_0">
            <joint armature="0.1" damping="15" />
            <position kp="3000" forcerange="-12 12" />
            <default class="size_0_limited">
                <joint range="-3.1415 3.1415" />
                <position ctrlrange="-3.1415 3.1415" />
            </default>
        </default>
        <default class="size_1">
            <joint armature="0.1" damping="15" />
            <position kp="3000" forcerange="-28 28" />
            <default class="size_1_limited">
                <joint range="-3.1415 3.1415" />
                <position ctrlrange="-3.1415 3.1415" />
            </default>
        </default>
        <default class="size_2">
            <joint armature="0.1" damping="15" />
            <position kp="3000" forcerange="-56 56" />
            <default class="size_2_limited">
                <joint range="-3.1415 3.1415" />
                <position ctrlrange="-3.1415 3.1415" />
            </default>
        </default>
        <default class="size_3">
            <joint armature="0.1" damping="200" />
            <position kp="3500" forcerange="-150 150" />
            <default class="size_3_limited">
                <joint range="-3.1415 3.1415" />
                <position ctrlrange="-3.1415 3.1415" />
            </default>
        </default>
        <default class="size_4">
            <joint armature="0.1" damping="15" />
            <position kp="3000" forcerange="-330 330" />
        </default>
    </default>

    <asset>
        <material name="black" specular="0.5" shininess="0.25" rgba="0.033 0.033 0.033 1" />
        <material name="jointgray" specular="0.5" shininess="0.25" rgba="0.278 0.278 0.278 1" />
        <material name="linkgray" specular="0.5" shininess="0.25" rgba="0.82 0.82 0.82 1" />
        <material name="urblue" specular="0.5" shininess="0.25" rgba="0.49 0.678 0.8 1" />

        <mesh name="base" file="base.stl" />
        <mesh name="shoulder" file="shoulder.stl" />
        <mesh name="upperarm" file="upperarm.stl" />
        <mesh name="forearm" file="forearm.stl" />
        <mesh name="wrist1" file="wrist1.stl" />
        <mesh name="wrist2" file="wrist2.stl" />
        <mesh name="wrist3" file="wrist3.stl" />
        <mesh name="body" file="body.stl" />
    </asset>

    <worldbody>
        <light name="spotlight" mode="targetbodycom" target="wrist_2_link" pos="0 -1 2" />

        <!-- BASE -->
        <body name="base_link" pos="0.07 0.13 1.15" quat="0.9238777 -0.3826805 0 0">
            <inertial mass="2.0" pos="0 0 0" quat="0.5 0.5 -0.5 0.5" diaginertia="0.005625 0.00305317 0.00305317" />
            <geom mesh="base" material="urblue" class="visual" />

            <!-- SHOULDER -->
            <body name="shoulder_link" pos="0 0 0.1519">
                <inertial mass="2.0" pos="0 0 0" diaginertia="0.00809316 0.00809316 0.005625" />
                <joint name="shoulder_pan_joint" class="size_2" axis="0 0 1" />
                <geom mesh="shoulder" material="linkgray" class="visual" />
                <!-- <geom class="collision" size="0.06 0.06" pos="0 0 -0.04" /> -->

                <!-- UPPERARM -->
                <body name="upper_arm_link" pos="0 0.1198 0" quat="1 0 1 0">
                    <inertial mass="3.42" pos="0 0 0.121825" diaginertia="0.0217285 0.0217285 0.00961875" />
                    <joint name="shoulder_lift_joint" class="size_2"/>
                    <geom mesh="upperarm" material="jointgray" class="visual" />
                    <!-- <geom class="collision" size="0.06 0.06" pos="0 0 -0.04" /> -->

                    <!-- FOREARM -->
                    <body name="forearm_link" pos="0 -0.0925 0.24365">
                        <inertial mass="1.26" pos="0 0 0.106625" diaginertia="0.00654681 0.00654681 0.00354375" />
                        <joint name="elbow_joint" class="size_1_limited" />
                        <geom mesh="forearm" material="linkgray" class="visual" />
                        <!-- <geom class="collision" pos="0 0.08 0" quat="1 1 0 0" size="0.055 0.06"/> -->
                        <!-- <geom class="collision" size="0.038 0.19" pos="0 0 0.2"/> -->

                        <!-- WRIST 1 -->
                        <body name="wrist_1_link" pos="0 0 0.21325" quat="1 0 1 0">
                            <inertial mass="0.8" pos="0 0 0" quat="0.5 0.5 -0.5 0.5" diaginertia="0.00225 0.002085 0.002085" />
                            <joint name="wrist_1_joint" class="size_0" />
                            <geom mesh="wrist1" material="jointgray" class="visual" />
                            <!-- <geom class="collision" pos="0 0.05 0" quat="1 1 0 0" size="0.04 0.07"/> -->

                            <!-- WRIST 2 -->
                            <body name="wrist_2_link" pos="0 0.08505 0">
                                <inertial mass="0.8" pos="0 0 0" quat="0.5 0.5 -0.5 0.5" diaginertia="0.00225 0.002085 0.002085" />
                                <joint name="wrist_2_joint" class="size_0" axis="0 0 1"/>
                                <geom mesh="wrist2" material="linkgray" class="visual" />
                                <!-- <geom class="collision" size="0.04 0.06" pos="0 0 0.04"/> -->
                                <!-- <geom class="collision" pos="0 0.02 0.1" quat="1 1 0 0" size="0.04 0.04"/> -->

                                <!-- WRIST 3 -->
                                <body name="wrist_3_link" pos="0 0 0.08535">
                                    <inertial mass="0.35" pos="0 0 0" quat="0.5 0.5 -0.5 0.5" diaginertia="0.000984375 0.000912187 0.000912187" />
                                    <joint name="wrist_3_joint" class="size_0" />
                                    <geom mesh="wrist3" material="jointgray" class="visual" />
                                    <!-- <geom class="eef_collision" pos="0 0.08 0" quat="1 1 0 0" size="0.04 0.02"/> -->
                                    <!-- <site name="attachment_site" pos="0 0.1 0" quat="-1 1 0 0"/> -->
                                </body>
                            </body>
                        </body>
                    </body>
                </body>
            </body>
        </body>

        <!-- BODY -->
        <body name="body" pos="0 0 0">
            <inertial mass="10.0" pos="0 0 0"/>
            <geom mesh="body" material="linkgray" class="visual" quat="0.7071 0 0 0.7071"/>
        </body>
    </worldbody>

    <actuator>
        <position class="size_2" name="shoulder_pan" joint="shoulder_pan_joint" />
        <position class="size_2" name="shoulder_lift" joint="shoulder_lift_joint" />
        <position class="size_1_limited" name="elbow" joint="elbow_joint" />
        <position class="size_0" name="wrist_1" joint="wrist_1_joint" />
        <position class="size_0" name="wrist_2" joint="wrist_2_joint" />
        <position class="size_0" name="wrist_3" joint="wrist_3_joint" />
    </actuator>

    <keyframe>
        <key name="home" qpos="-1.5708 1.5708 0.098 1.5708 3.1415 0" ctrl="-1.5708 1.5708 0.098 1.5708 3.1415 0" />
    </keyframe>

</mujoco>