<mujoco model="adam">
    <compiler angle="radian" meshdir="meshes" autolimits="true" />

    <default>
        <joint axis="0 1 0" range="-6.28319 6.28319" />
        <position ctrlrange="-6.2831 6.2831" />

        <default class="visual">
            <geom type="mesh" contype="0" conaffinity="0" group="2" />
        </default>
        <default class="cylinder_collision">
            <geom type="cylinder" group="3" />
        </default>
        <default class="capsule_collision">
            <geom type="capsule" group="3" />
        </default>
        <default class="box_collision">
            <geom type="box" group="3" />
        </default>
        <site size="0.001" rgba="0.5 0.5 0.5 0.3" group="4" />

        <!-- Reference: https://www.universal-robots.com/articles/ur/robot-care-maintenance/max-joint-torques/ -->
        <default class="size_0">
            <joint armature="0.1" damping="15" />
            <position kp="3000" forcerange="-12 12" />
            <default class="size_0_limited">
                <joint range="-3.1415 3.1415" />
                <position ctrlrange="-3.1415 3.1415" />
            </default>
        </default>
        <default class="size_1">
            <joint armature="0.1" damping="15" />
            <position kp="3000" forcerange="-28 28" />
            <default class="size_1_limited">
                <joint range="-3.1415 3.1415" />
                <position ctrlrange="-3.1415 3.1415" />
            </default>
        </default>
        <default class="size_2">
            <joint armature="0.1" damping="15" />
            <position kp="3000" forcerange="-56 56" />
            <default class="size_2_limited">
                <joint range="-3.1415 3.1415" />
                <position ctrlrange="-3.1415 3.1415" />
            </default>
        </default>
        <default class="size_3">
            <joint armature="0.1" damping="200" />
            <position kp="3500" forcerange="-150 150" />
            <default class="size_3_limited">
                <joint range="-3.1415 3.1415" />
                <position ctrlrange="-3.1415 3.1415" />
            </default>
        </default>
        <default class="size_4">
            <joint armature="0.1" damping="15" />
            <position kp="3000" forcerange="-330 330" />
        </default>
    </default>

    <asset>
        <material name="black" specular="0.5" shininess="0.25" rgba="0.033 0.033 0.033 1" />
        <material name="dark_gray" specular="0.5" shininess="0.25" rgba="0.278 0.278 0.278 1" />
        <material name="light_gray" specular="0.9" shininess="0.25" reflectance="0.9" rgba="0.50 0.50 0.50 1" />
        <material name="blue" specular="0.5" shininess="0.25" rgba="0.49 0.678 0.8 1" />

        <mesh name="base" file="base.stl" />
        <mesh name="shoulder_rubber" file="shoulder_rubber.stl" />
        <mesh name="shoulder_body" file="shoulder_body.stl" />
        <mesh name="shoulder_cap" file="shoulder_cap.stl" />
        <mesh name="shoulder_screws" file="shoulder_screws.stl" />
        <mesh name="upperarm_rubber" file="upperarm_rubber.stl" />
        <mesh name="upperarm_body" file="upperarm_body.stl" />
        <mesh name="upperarm_cap" file="upperarm_cap.stl" />
        <mesh name="upperarm_screws" file="upperarm_screws.stl" />
        <mesh name="upperarm_link_body" file="upperarm_link_body.stl" />
        <mesh name="upperarm_rubber_2" file="upperarm_rubber_2.stl" />
        <mesh name="upperarm_rubber_3" file="upperarm_rubber_3.stl" />
        <mesh name="forearm_body" file="forearm_body.stl" />
        <mesh name="forearm_body_2" file="forearm_body_2.stl" />
        <mesh name="forearm_cap" file="forearm_cap.stl" />
        <mesh name="forearm_link_body" file="forearm_link_body.stl" />
        <mesh name="forearm_rubber" file="forearm_rubber.stl" />
        <mesh name="forearm_rubber_2" file="forearm_rubber_2.stl" />
        <mesh name="wrist_1_rubber" file="wrist_1_rubber.stl" />
        <mesh name="wrist_1_body" file="wrist_1_body.stl" />
        <mesh name="wrist_1_cap" file="wrist_1_cap.stl" />
        <mesh name="wrist_2_rubber" file="wrist_2_rubber.stl" />
        <mesh name="wrist_2_body" file="wrist_2_body.stl" />
        <mesh name="wrist_2_cap" file="wrist_2_cap.stl" />
        <mesh name="wrist_3_rubber" file="wrist_3_rubber.stl" />
        <mesh name="wrist_3_body" file="wrist_3_body.stl" />
        <mesh name="wrist_3_cap" file="wrist_3_cap.stl" />
        <mesh name="end_effector_rubber" file="end_effector_rubber.stl" />
        <mesh name="end_effector_body" file="end_effector_body.stl" />
        <mesh name="body" file="body.stl" />
    </asset>

    <worldbody>
        <light name="spotlight" mode="targetbodycom" target="wrist_2_link_left" pos="0 -1 2" />

        <!-- BODY -->
        <body name="body" pos="0 0 0">
            <inertial mass="10.0" pos="0 0 0"/>
            <geom mesh="body" material="light_gray" class="visual" quat="0.7071 0 0 0.7071" pos="0 0 -0.02"/>
            <geom class="box_collision" size="0.15 0.15 0.2" pos="0 0 1.0" />
            <geom class="cylinder_collision" size="0.3 0.1" pos="0 0 0.1" />
            <geom class="box_collision" size="0.2 0.2 0.4" pos="0 0 0.4" />

            <!-- LEFT MANIPULATOR -->
            <!-- BASE -->
            <body name="base_link_left" pos="0.07 0.12625 1.15435" quat="0.9238777 -0.3826805 0 0">
                <inertial mass="2.0" pos="0 0 0" quat="0.5 0.5 -0.5 0.5" diaginertia="0.005625 0.00305317 0.00305317" />
                <geom mesh="base" material="light_gray" class="visual" quat="0.7071 0.7071 0 0"/>

                <!-- SHOULDER -->
                <body name="shoulder_link_left" pos="0 0 0.1519">
                    <inertial mass="2.0" pos="0 0 0" diaginertia="0.00809316 0.00809316 0.005625" />
                    <joint name="shoulder_pan_joint_left" class="size_2" axis="0 0 1" />
                    <geom mesh="shoulder_rubber" material="black" class="visual" quat="0.7071 0.7071 0 0" pos="0 0 -0.0675"/>
                    <geom mesh="shoulder_body" material="dark_gray" class="visual" quat="0 1 0 0" pos="0 0.0675 -0.002"/>
                    <geom mesh="shoulder_cap" material="blue" class="visual" quat="0 1 0 0" pos="0 0.0675 -0.002"/>
                    <geom mesh="shoulder_screws" material="light_gray" class="visual" quat="0 0 0 1" pos="0 0.1525 -0.002"/>
                    <geom class="cylinder_collision" size="0.06 0.1" pos="0 0 -0.05" />

                    <!-- UPPERARM -->
                    <body name="upper_arm_link_left" pos="0 0.1198 0" quat="1 0 1 0">
                        <inertial mass="3.42" pos="0 0 0.121825" diaginertia="0.0217285 0.0217285 0.00961875" />
                        <joint name="shoulder_lift_joint_left" class="size_2"/>
                        <geom mesh="upperarm_rubber" material="black" class="visual" pos="0.002 -0.066 0"/>
                        <geom mesh="upperarm_body" material="dark_gray" class="visual" pos="0.002 -0.066 0"/>
                        <geom mesh="upperarm_cap" material="blue" class="visual" pos="0.002 -0.066 0"/>
                        <geom mesh="upperarm_screws" material="light_gray" class="visual" quat="0 0 1 0" pos="0.002 -0.151 0"/>
                        <geom mesh="upperarm_rubber_2" material="black" class="visual" pos="0.0022 0.0011 0.1992"/>
                        <geom mesh="upperarm_link_body" material="light_gray" class="visual" pos="0.0022 0.0011 0.1992"/>
                        <geom mesh="upperarm_rubber_3" material="black" class="visual" pos="0.0022 0.0011 0.1992"/>
                        <geom class="cylinder_collision" size="0.06 0.125" pos="0 0 0.075" />
                        <geom mesh="forearm_body" material="dark_gray" class="visual" quat="0.7071 0 0.7071 0" pos="0.0022 0.0011 0.243"/>
                        <geom mesh="forearm_cap" material="blue" class="visual" quat="0.7071 0 0.7071 0" pos="0.0022 0.0011 0.243"/>
                        <geom mesh="forearm_rubber" material="black" class="visual" quat="0.7071 0 0 0.7071" pos="0.0022 0.0011 0.243"/>

                        <!-- FOREARM -->
                        <body name="forearm_link_left" pos="0 -0.0925 0.24365">
                            <inertial mass="1.26" pos="0 0 0.106625" diaginertia="0.00654681 0.00654681 0.00354375" />
                            <joint name="elbow_joint_left" class="size_1_limited" />
                            <geom mesh="forearm_body_2" material="dark_gray" class="visual" quat="0.5 0.5 -0.5 -0.5" pos="0.002 0.001 0"/>
                            <geom mesh="forearm_rubber_2" material="black" class="visual" pos="0.002 0.001 -0.014"/>
                            <geom mesh="forearm_link_body" material="light_gray" class="visual" pos="0.002 0.001 0.1125"/>
                            <geom class="cylinder_collision" size="0.04 0.11" pos="0 0 0.07" />
                            <geom class="cylinder_collision" size="0.05 0.1" pos="0 0.06 0" quat="0.7071 0.7171 0 0"/>
                            <geom mesh="wrist_1_rubber" material="black" class="visual" quat="0.7071 0 0.7071 0" pos="0.002 0.001 0.2125"/>
                            <geom mesh="wrist_1_body" material="dark_gray" class="visual" quat="0 -0.7071 0 0.7071" pos="0.0015 0.001 0.2125"/>
                            <geom mesh="wrist_1_cap" material="blue" class="visual" quat="0 0.7071 0 0.7071" pos="0.002 -0.005 0.2125"/>

                            <!-- WRIST 1 -->
                            <body name="wrist_1_link_left" pos="0 0 0.21325" quat="1 0 1 0">
                                <inertial mass="0.8" pos="0 0 0" quat="0.5 0.5 -0.5 0.5" diaginertia="0.00225 0.002085 0.002085" />
                                <joint name="wrist_1_joint_left" class="size_0" />
                                <geom class="cylinder_collision" size="0.04 0.05" pos="0 0 0" quat="0.7071 0.7171 0 0"/>
                                <geom mesh="wrist_2_rubber" material="black" class="visual" quat="0.7071 0 0 0.7071" pos="0.0015 0.0087 -0.0005"/>
                                <geom mesh="wrist_2_body" material="dark_gray" class="visual" quat="0.5 -0.5 0.5 -0.5" pos="0.0015 0.084 -0.0005"/>
                                <geom mesh="wrist_2_cap" material="blue" class="visual" quat="0.5 -0.5 -0.5 0.5" pos="0.0015 0.084 -0.007"/>

                                <!-- WRIST 2 -->
                                <body name="wrist_2_link_left" pos="0 0.08505 0">
                                    <inertial mass="0.8" pos="0 0 0" quat="0.5 0.5 -0.5 0.5" diaginertia="0.00225 0.002085 0.002085" />
                                    <joint name="wrist_2_joint_left" class="size_0" axis="0 0 1"/>
                                    <geom class="cylinder_collision" size="0.04 0.05" pos="0 0 0"/>
                                    <geom mesh="wrist_3_rubber" material="black" class="visual" quat="0.7071 0 0.7071 0" pos="0.001 -0.001 0.083"/>
                                    <geom mesh="wrist_3_body" material="dark_gray" class="visual" quat="0 0.7071 0 -0.7071" pos="0.001 -0.001 0.083"/>
                                    <geom mesh="wrist_3_cap" material="blue" class="visual" quat="0 0.7071 0 0.7071" pos="0.001 -0.008 0.083"/>

                                    <!-- WRIST 3 -->
                                    <body name="wrist_3_link_left" pos="0 0 0.08535">
                                        <inertial mass="0.35" pos="0 0 0" quat="0.5 0.5 -0.5 0.5" diaginertia="0.000984375 0.000912187 0.000912187" />
                                        <joint name="wrist_3_joint_left" class="size_0" />
                                        <geom mesh="end_effector_rubber" material="black" class="visual" quat="0.7071 0.7071 0 0" pos="0.001 0.04 -0.0025"/>
                                        <geom mesh="end_effector_body" material="light_gray" class="visual" quat="0.7071 0.7071 0 0" pos="0.001 0.04 -0.0025"/>
                                        <geom class="cylinder_collision" size="0.04 0.065" quat="0.7071 0.7071 0 0" pos="0 0.015 0"/>
                                    </body>
                                </body>
                            </body>
                        </body>
                    </body>
                </body>
            </body>

            <!-- RIGHT MANIPULATOR -->
            <!-- BASE -->
            <body name="base_link_right" pos="0.07 -0.12625 1.15435" quat="0 0 -0.3826834  0.9238795">
                <inertial mass="2.0" pos="0 0 0" quat="0.5 0.5 -0.5 0.5" diaginertia="0.005625 0.00305317 0.00305317" />
                <geom mesh="base" material="light_gray" class="visual" quat="0.7071 0.7071 0 0"/>

                <!-- SHOULDER -->
                <body name="shoulder_link_right" pos="0 0 0.1519">
                    <inertial mass="2.0" pos="0 0 0" diaginertia="0.00809316 0.00809316 0.005625" />
                    <joint name="shoulder_pan_joint_right" class="size_2" axis="0 0 1" />
                    <geom mesh="shoulder_rubber" material="black" class="visual" quat="0.7071 0.7071 0 0" pos="0 0 -0.0675"/>
                    <geom mesh="shoulder_body" material="dark_gray" class="visual" quat="0 1 0 0" pos="0 0.0675 -0.002"/>
                    <geom mesh="shoulder_cap" material="blue" class="visual" quat="0 1 0 0" pos="0 0.0675 -0.002"/>
                    <geom mesh="shoulder_screws" material="light_gray" class="visual" quat="0 0 0 1" pos="0 0.1525 -0.002"/>
                    <geom class="cylinder_collision" size="0.06 0.1" pos="0 0 -0.05" />

                    <!-- UPPERARM -->
                    <body name="upper_arm_link_right" pos="0 0.1198 0" quat="1 0 1 0">
                        <inertial mass="3.42" pos="0 0 0.121825" diaginertia="0.0217285 0.0217285 0.00961875" />
                        <joint name="shoulder_lift_joint_right" class="size_2"/>
                        <geom mesh="upperarm_rubber" material="black" class="visual" pos="0.002 -0.066 0"/>
                        <geom mesh="upperarm_body" material="dark_gray" class="visual" pos="0.002 -0.066 0"/>
                        <geom mesh="upperarm_cap" material="blue" class="visual" pos="0.002 -0.066 0"/>
                        <geom mesh="upperarm_screws" material="light_gray" class="visual" quat="0 0 1 0" pos="0.002 -0.151 0"/>
                        <geom mesh="upperarm_rubber_2" material="black" class="visual" pos="0.0022 0.0011 0.1992"/>
                        <geom mesh="upperarm_link_body" material="light_gray" class="visual" pos="0.0022 0.0011 0.1992"/>
                        <geom mesh="upperarm_rubber_3" material="black" class="visual" pos="0.0022 0.0011 0.1992"/>
                        <geom class="cylinder_collision" size="0.06 0.125" pos="0 0 0.075" />
                        <geom mesh="forearm_body" material="dark_gray" class="visual" quat="0.7071 0 0.7071 0" pos="0.0022 0.0011 0.243"/>
                        <geom mesh="forearm_cap" material="blue" class="visual" quat="0.7071 0 0.7071 0" pos="0.0022 0.0011 0.243"/>
                        <geom mesh="forearm_rubber" material="black" class="visual" quat="0.7071 0 0 0.7071" pos="0.0022 0.0011 0.243"/>

                        <!-- FOREARM -->
                        <body name="forearm_link_right" pos="0 -0.0925 0.24365">
                            <inertial mass="1.26" pos="0 0 0.106625" diaginertia="0.00654681 0.00654681 0.00354375" />
                            <joint name="elbow_joint_right" class="size_1_limited" />
                            <geom mesh="forearm_body_2" material="dark_gray" class="visual" quat="0.5 0.5 -0.5 -0.5" pos="0.002 0.001 0"/>
                            <geom mesh="forearm_rubber_2" material="black" class="visual" pos="0.002 0.001 -0.014"/>
                            <geom mesh="forearm_link_body" material="light_gray" class="visual" pos="0.002 0.001 0.1125"/>
                            <geom class="cylinder_collision" size="0.04 0.11" pos="0 0 0.07" />
                            <geom class="cylinder_collision" size="0.05 0.1" pos="0 0.06 0" quat="0.7071 0.7171 0 0"/>
                            <geom mesh="wrist_1_rubber" material="black" class="visual" quat="0.7071 0 0.7071 0" pos="0.002 0.001 0.2125"/>
                            <geom mesh="wrist_1_body" material="dark_gray" class="visual" quat="0 -0.7071 0 0.7071" pos="0.0015 0.001 0.2125"/>
                            <geom mesh="wrist_1_cap" material="blue" class="visual" quat="0 0.7071 0 0.7071" pos="0.002 -0.005 0.2125"/>

                            <!-- WRIST 1 -->
                            <body name="wrist_1_link_right" pos="0 0 0.21325" quat="1 0 1 0">
                                <inertial mass="0.8" pos="0 0 0" quat="0.5 0.5 -0.5 0.5" diaginertia="0.00225 0.002085 0.002085" />
                                <joint name="wrist_1_joint_right" class="size_0" />
                                <geom class="cylinder_collision" size="0.04 0.05" pos="0 0 0" quat="0.7071 0.7171 0 0"/>
                                <geom mesh="wrist_2_rubber" material="black" class="visual" quat="0.7071 0 0 0.7071" pos="0.0015 0.0087 -0.0005"/>
                                <geom mesh="wrist_2_body" material="dark_gray" class="visual" quat="0.5 -0.5 0.5 -0.5" pos="0.0015 0.084 -0.0005"/>
                                <geom mesh="wrist_2_cap" material="blue" class="visual" quat="0.5 -0.5 -0.5 0.5" pos="0.0015 0.084 -0.007"/>

                                <!-- WRIST 2 -->
                                <body name="wrist_2_link_right" pos="0 0.08505 0">
                                    <inertial mass="0.8" pos="0 0 0" quat="0.5 0.5 -0.5 0.5" diaginertia="0.00225 0.002085 0.002085" />
                                    <joint name="wrist_2_joint_right" class="size_0" axis="0 0 1"/>
                                    <geom class="cylinder_collision" size="0.04 0.05" pos="0 0 0"/>
                                    <geom mesh="wrist_3_rubber" material="black" class="visual" quat="0.7071 0 0.7071 0" pos="0.001 -0.001 0.083"/>
                                    <geom mesh="wrist_3_body" material="dark_gray" class="visual" quat="0 0.7071 0 -0.7071" pos="0.001 -0.001 0.083"/>
                                    <geom mesh="wrist_3_cap" material="blue" class="visual" quat="0 0.7071 0 0.7071" pos="0.001 -0.008 0.083"/>

                                    <!-- WRIST 3 -->
                                    <body name="wrist_3_link_right" pos="0 0 0.08535">
                                        <inertial mass="0.35" pos="0 0 0" quat="0.5 0.5 -0.5 0.5" diaginertia="0.000984375 0.000912187 0.000912187" />
                                        <joint name="wrist_3_joint_right" class="size_0" />
                                        <geom mesh="end_effector_rubber" material="black" class="visual" quat="0.7071 0.7071 0 0" pos="0.001 0.04 -0.0025"/>
                                        <geom mesh="end_effector_body" material="light_gray" class="visual" quat="0.7071 0.7071 0 0" pos="0.001 0.04 -0.0025"/>
                                        <geom class="cylinder_collision" size="0.04 0.065" quat="0.7071 0.7071 0 0" pos="0 0.015 0"/>
                                    </body>
                                </body>
                            </body>
                        </body>
                    </body>
                </body>
            </body>
        </body>
    </worldbody>

    <actuator>
        <position class="size_2" name="shoulder_pan_left" joint="shoulder_pan_joint_left" />
        <position class="size_2" name="shoulder_lift_left" joint="shoulder_lift_joint_left" />
        <position class="size_1_limited" name="elbow_left" joint="elbow_joint_left" />
        <position class="size_0" name="wrist_1_left" joint="wrist_1_joint_left" />
        <position class="size_0" name="wrist_2_left" joint="wrist_2_joint_left" />
        <position class="size_0" name="wrist_3_left" joint="wrist_3_joint_left" />
        <position class="size_2" name="shoulder_pan_right" joint="shoulder_pan_joint_right" />
        <position class="size_2" name="shoulder_lift_right" joint="shoulder_lift_joint_right" />
        <position class="size_1_limited" name="elbow_right" joint="elbow_joint_right" />
        <position class="size_0" name="wrist_1_right" joint="wrist_1_joint_right" />
        <position class="size_0" name="wrist_2_right" joint="wrist_2_joint_right" />
        <position class="size_0" name="wrist_3_right" joint="wrist_3_joint_right" />
    </actuator>

    <keyframe>
        <key name="home" qpos="1.5708 0.58905 -0.098 -1.5708 3.1415 0 -1.5708 2.4435 0.0 -1.5708 3.1415 0.0" ctrl="1.5708 0.58905 -0.098 -1.5708 3.1415 0 -1.5708 2.4435 0.0 -1.5708 3.1415 0.0" />
    </keyframe>

</mujoco>